Workbook

Sheet onepage_summary (6)
A1: PadL | B1: Model | C1: Npages | D1: Acc_mean | E1: Prec_mean | F1: Rec_mean | G1: F1_mean | H1: Bandwidth Overhead
A2: 1 | B2: DF | C2: 95 | D2: 0.766438 | E2: 0.753491 | F2: 0.756292 | G2: 0.754272 | H2: 110.43
A3: 50 | B3: DF | C3: 95 | D3: 0.764048 | E3: 0.778678 | F3: 0.764024 | G3: 0.750423 | H3: =VLOOKUP(A3,Sheet1!$S$14:$T$34,2,FALSE)*100 -> 120.03
A4: 100 | B4: DF | C4: 95 | D4: 0.757738 | E4: 0.762466 | F4: 0.757708 | G4: 0.738777 | H4: =VLOOKUP(A4,Sheet1!$S$14:$T$34,2,FALSE)*100 -> 129.85
A5: 150 | B5: DF | C5: 95 | D5: 0.749684 | E5: 0.756123 | F5: 0.749728 | G5: 0.732765 | H5: =VLOOKUP(A5,Sheet1!$S$14:$T$34,2,FALSE)*100 -> 139.67
A6: 200 | B6: DF | C6: 95 | D6: 0.747351 | E6: 0.764134 | F6: 0.747363 | G6: 0.73226 | H6: =VLOOKUP(A6,Sheet1!$S$14:$T$34,2,FALSE)*100 -> 149.44
A7: 300 | B7: DF | C7: 95 | D7: 0.747101 | E7: 0.761054 | F7: 0.747228 | G7: 0.731466 | H7: =VLOOKUP(A7,Sheet1!$S$14:$T$34,2,FALSE)*100 -> 169.15
A8: 400 | B8: DF | C8: 95 | D8: 0.739194 | E8: 0.755141 | F8: 0.739391 | G8: 0.729762 | H8: =VLOOKUP(A8,Sheet1!$S$14:$T$34,2,FALSE)*100 -> 188.58
A9: 500 | B9: DF | C9: 95 | D9: 0.726898 | E9: 0.744297 | F9: 0.727027 | G9: 0.715881 | H9: =VLOOKUP(A9,Sheet1!$S$14:$T$34,2,FALSE)*100 -> 208.37
A10: 600 | B10: DF | C10: 95 | D10: 0.720878 | E10: 0.747696 | F10: 0.72118 | G10: 0.710831 | H10: =VLOOKUP(A10,Sheet1!$S$14:$T$34,2,FALSE)*100 -> 228.35
A11: 700 | B11: DF | C11: 95 | D11: 0.707024 | E11: 0.729913 | F11: 0.707242 | G11: 0.694082 | H11: =VLOOKUP(A11,Sheet1!$S$14:$T$34,2,FALSE)*100 -> 247.55
A12: 800 | B12: DF | C12: 95 | D12: 0.700051 | E12: 0.738248 | F12: 0.700299 | G12: 0.687925 | H12: =VLOOKUP(A12,Sheet1!$S$14:$T$34,2,FALSE)*100 -> 266.91
A13: 900 | B13: DF | C13: 95 | D13: 0.682848 | E13: 0.726065 | F13: 0.683061 | G13: 0.667494 | H13: =VLOOKUP(A13,Sheet1!$S$14:$T$34,2,FALSE)*100 -> 287.17
A14: 1000 | B14: DF | C14: 95 | D14: 0.671593 | E14: 0.717721 | F14: 0.67178 | G14: 0.653639 | H14: =VLOOKUP(A14,Sheet1!$S$14:$T$34,2,FALSE)*100 -> 306.3
... A19: 1500 | B19: DF | C19: 95 | D19: 0.637384 | E19: 0.723037 | F19: 0.637487 | G19: 0.598867 | H19: =VLOOKUP(A19,Sheet1!$S$14:$T$34,2,FALSE)*100 -> 404.19
A20: 1 | B20: RF | C20: 95 | D20: 0.785005 | E20: 0.796358 | F20: 0.785171 | G20: 0.782717 | H20: 110.43
A21: 50 | B21: RF | C21: 95 | D21: 0.780589 | E21: 0.795219 | F21: 0.780796 | G21: 0.777785 | H21: =VLOOKUP(A21,Sheet1!$S$14:$T$34,2,FALSE)*100 -> 120.03
A22: 100 | B22: RF | C22: 95 | D22: 0.779972 | E22: 0.794171 | F22: 0.780186 | G22: 0.775164 | H22: =VLOOKUP(A22,Sheet1!$S$14:$T$34,2,FALSE)*100 -> 129.85
A23: 150 | B23: RF | C23: 95 | D23: 0.772068 | E23: 0.792715 | F23: 0.772303 | G23: 0.765649 | H23: =VLOOKUP(A23,Sheet1!$S$14:$T$34,2,FALSE)*100 -> 139.67
A24: 200 | B24: RF | C24: 95 | D24: 0.759661 | E24: 0.775986 | F24: 0.759924 | G24: 0.752621 | H24: =VLOOKUP(A24,Sheet1!$S$14:$T$34,2,FALSE)*100 -> 149.44
A25: 300 | B25: RF | C25: 95 | D25: 0.748825 | E25: 0.766158 | F25: 0.749114 | G25: 0.742192 | H25: =VLOOKUP(A25,Sheet1!$S$14:$T$34,2,FALSE)*100 -> 169.15
A26: 400 | B26: RF | C26: 95 | D26: 0.734305 | E26: 0.755699 | F26: 0.734614 | G26: 0.728881 | H26: =VLOOKUP(A26,Sheet1!$S$14:$T$34,2,FALSE)*100 -> 188.58
A27: 500 | B27: RF | C27: 95 | D27: 0.733722 | E27: 0.757052 | F27: 0.734028 | G27: 0.727306 | H27: =VLOOKUP(A27,Sheet1!$S$14:$T$34,2,FALSE)*100 -> 208.37
A28: 600 | B28: RF | C28: 95 | D28: 0.720465 | E28: 0.745254 | F28: 0.720758 | G28: 0.713407 | H28: =VLOOKUP(A28,Sheet1!$S$14:$T$34,2,FALSE)*100 -> 228.35
A29: 700 | B29: RF | C29: 95 | D29: 0.699671 | E29: 0.726246 | F29: 0.699987 | G29: 0.691133 | H29: =VLOOKUP(A29,Sheet1!$S$14:$T$34,2,FALSE)*100 -> 247.55
A30: 800 | B30: RF | C30: 95 | D30: 0.68666 | E30: 0.716686 | F30: 0.68694 | G30: 0.677027 | H30: =VLOOKUP(A30,Sheet1!$S$14:$T$34,2,FALSE)*100 -> 266.91
A31: 900 | B31: RF | C31: 95 | D31: 0.669918 | E31: 0.704581 | F31: 0.670204 | G31: 0.656531 | H31: =VLOOKUP(A31,Sheet1!$S$14:$T$34,2,FALSE)*100 -> 287.17
A32: 1000 | B32: RF | C32: 95 | D32: 0.661775 | E32: 0.701609 | F32: 0.662037 | G32: 0.646259 | H32: =VLOOKUP(A32,Sheet1!$S$14:$T$34,2,FALSE)*100 -> 306.3
... A37: 1500 | B37: RF | C37: 95 | D37: 0.629459 | E37: 0.703586 | F37: 0.629606 | G37: 0.595195 | H37: =VLOOKUP(A37,Sheet1!$S$14:$T$34,2,FALSE)*100 -> 404.19
A38: 1 | B38: TikTok | C38: 95 | D38: 0.794031 | E38: 0.804487 | F38: 0.79418 | G38: 0.789413 | H38: 110.43
A39: 50 | B39: TikTok | C39: 95 | D39: 0.786868 | E39: 0.799045 | F39: 0.787022 | G39: 0.781668 | H39: =VLOOKUP(A39,Sheet1!$S$14:$T$34,2,FALSE)*100 -> 120.03
A40: 100 | B40: TikTok | C40: 95 | D40: 0.778814 | E40: 0.78972 | F40: 0.778971 | G40: 0.773924 | H40: =VLOOKUP(A40,Sheet1!$S$14:$T$34,2,FALSE)*100 -> 129.85
A41: 150 | B41: TikTok | C41: 95 | D41: 0.773965 | E41: 0.788397 | F41: 0.774143 | G41: 0.767925 | H41: =VLOOKUP(A41,Sheet1!$S$14:$T$34,2,FALSE)*100 -> 139.67
A42: 200 | B42: TikTok | C42: 95 | D42: 0.767128 | E42: 0.784512 | F42: 0.767374 | G42: 0.762514 | H42: =VLOOKUP(A42,Sheet1!$S$14:$T$34,2,FALSE)*100 -> 149.44
A43: 300 | B43: TikTok | C43: 95 | D43: 0.749317 | E43: 0.766577 | F43: 0.749488 | G43: 0.74114 | H43: =VLOOKUP(A43,Sheet1!$S$14:$T$34,2,FALSE)*100 -> 169.15
A44: 400 | B44: TikTok | C44: 95 | D44: 0.739789 | E44: 0.760138 | F44: 0.739992 | G44: 0.730349 | H44: =VLOOKUP(A44,Sheet1!$S$14:$T$34,2,FALSE)*100 -> 188.58
A45: 500 | B45: TikTok | C45: 95 | D45: 0.725078 | E45: 0.748466 | F45: 0.725245 | G45: 0.714227 | H45: =VLOOKUP(A45,Sheet1!$S$14:$T$34,2,FALSE)*100 -> 208.37
A46: 600 | B46: TikTok | C46: 95 | D46: 0.711866 | E46: 0.737696 | F46: 0.712114 | G46: 0.699182 | H46: =VLOOKUP(A46,Sheet1!$S$14:$T$34,2,FALSE)*100 -> 228.35
A47: 700 | B47: TikTok | C47: 95 | D47: 0.700404 | E47: 0.72708 | F47: 0.700469 | G47: 0.684003 | H47: =VLOOKUP(A47,Sheet1!$S$14:$T$34,2,FALSE)*100 -> 247.55
A48: 800 | B48: TikTok | C48: 95 | D48: 0.691243 | E48: 0.713929 | F48: 0.691424 | G48: 0.674017 | H48: =VLOOKUP(A48,Sheet1!$S$14:$T$34,2,FALSE)*100 -> 266.91
...

Sheet onepage_summary (5)
A1: PadL | B1: Model | C1: Npages | D1: Acc_mean | E1: Prec_mean | F1: Rec_mean | G1: F1_mean | H1: Bandwidth overhead
A2: 25 | B2: DF | C2: 95 | D2: 0.766256 | E2: 0.774828 | F2: 0.766245 | G2: 0.752811 | H2: =VLOOKUP(A2,Sheet1!$S$14:$T$29,2,FALSE) -> 1.1515
A3: 50 | B3: DF | C3: 95 | D3: 0.764048 | E3: 0.778678 | F3: 0.764024 | G3: 0.750423 | H3: =VLOOKUP(A3,Sheet1!$S$14:$T$29,2,FALSE) -> 1.2003
A4: 75 | B4: DF | C4: 95 | D4: 0.760904 | E4: 0.781001 | F4: 0.760906 | G4: 0.745063 | H4: =VLOOKUP(A4,Sheet1!$S$14:$T$29,2,FALSE) -> 1.2495
A5: 100 | B5: DF | C5: 95 | D5: 0.757738 | E5: 0.762466 | F5: 0.757708 | G5: 0.738777 | H5: =VLOOKUP(A5,Sheet1!$S$14:$T$29,2,FALSE) -> 1.2985
A6: 125 | B6: DF | C6: 95 | D6: 0.750146 | E6: 0.752374 | F6: 0.750148 | G6: 0.731149 | H6: =VLOOKUP(A6,Sheet1!$S$14:$T$29,2,FALSE) -> 1.3472
A7: 150 | B7: DF | C7: 95 | D7: 0.749684 | E7: 0.756123 | F7: 0.749728 | G7: 0.732765 | H7: =VLOOKUP(A7,Sheet1!$S$14:$T$29,2,FALSE) -> 1.3967
A8: 175 | B8: DF | C8: 95 | D8: 0.748231 | E8: 0.757592 | F8: 0.748355 | G8: 0.733214 | H8: =VLOOKUP(A8,Sheet1!$S$14:$T$29,2,FALSE) -> 1.4468
A9: 200 | B9: DF | C9: 95 | D9: 0.747351 | E9: 0.764134 | F9: 0.747363 | G9: 0.73326 | H9: =VLOOKUP(A9,Sheet1!$S$14:$T$29,2,FALSE) -> 1.4944
A10: 300 | B10: DF | C10: 95 | D10: 0.747101 | E10: 0.761054 | F10: 0.747228 | G10: 0.735466 | H10: =VLOOKUP(A10,Sheet1!$S$14:$T$29,2,FALSE) -> 1.6915
A11: 400 | B11: DF | C11: 95 | D11: 0.739194 | E11: 0.755141 | F11: 0.739391 | G11: 0.729762 | H11: =VLOOKUP(A11,Sheet1!$S$14:$T$29,2,FALSE) -> 1.8858
A12: 500 | B12: DF | C12: 95 | D12: 0.726898 | E12: 0.744297 | F12: 0.727027 | G12: 0.715881 | H12: =VLOOKUP(A12,Sheet1!$S$14:$T$29,2,FALSE) -> 2.0837
A13: 600 | B13: DF | C13: 95 | D13: 0.720878 | E13: 0.747696 | F13: 0.72118 | G13: 0.710831 | H13: =VLOOKUP(A13,Sheet1!$S$14:$T$29,2,FALSE) -> 2.2835
... A124: 1000 | B124: VarCNN | C124: 95 | D124: 0.66308 | E124: 0.705041 | F124: 0.663295 | G124: 0.646913 | H124: =VLOOKUP(A124,Sheet1!$S$14:$T$29,2,FALSE) -> 3.063

Sheet onepage_summary_highpadl
A1: PadL | B1: Model | C1: Npages | D1: Accuracy_mean | E1: Precision_mean | F1: Recall_mean | G1: F1_mean | H1: Column1
A2: 25 | B2: DF | C2: 10 | D2: 0.79453 | E2: 0.81113 | F2: 0.7947 | G2: 0.79129 | H2: {='onepage_summary (6)'!H:H} -> #VALUE!
A3: 50 | B3: DF | C3: 10 | D3: 0.79273 | E3: 0.81113 | F3: 0.79291 | G3: 0.78884 | H3: {='onepage_summary (6)'!H:H} -> #VALUE!
A4: 75 | B4: DF | C4: 10 | D4: 0.74039 | E4: 0.72934 | F4: 0.74009 | G4: 0.71589 | H4: {='onepage_summary (6)'!H:H} -> #VALUE!
A5: 100 | B5: DF | C5: 10 | D5: 0.73645 | E5: 0.69795 | F5: 0.73609 | G5: 0.70086 | H5: {='onepage_summary (6)'!H:H} -> #VALUE!
A6: 125 | B6: DF | C6: 10 | D6: 0.75664 | E6: 0.77368 | F6: 0.75644 | G6: 0.7449 | H6: {='onepage_summary (6)'!H:H} -> #VALUE!
A7: 150 | B7: DF | C7: 10 | D7: 0.7557 | E7: 0.74314 | F7: 0.75552 | G7: 0.73625 | H7: {='onepage_summary (6)'!H:H} -> #VALUE!
A8: 175 | B8: DF | C8: 10 | D8: 0.75317 | E8: 0.74427 | F8: 0.75301 | G8: 0.73335 | H8: {='onepage_summary (6)'!H:H} -> #VALUE!
A9: 200 | B9: DF | C9: 10 | D9: 0.75382 | E9: 0.78441 | F9: 0.75366 | G9: 0.73624 | H9: {='onepage_summary (6)'!H:H} -> #VALUE!
A10: 300 | B10: DF | C10: 10 | D10: 0.73496 | E10: 0.75533 | F10: 0.73491 | G10: 0.72178 | H10: {='onepage_summary (6)'!H:H} -> #VALUE!
A11: 400 | B11: DF | C11: 10 | D11: 0.72881 | E11: 0.71718 | F11: 0.72876 | G11: 0.70996 | H11: {='onepage_summary (6)'!H:H} -> #VALUE!
A12: 500 | B12: DF | C12: 10 | D12: 0.74462 | E12: 0.77045 | F12: 0.74492 | G12: 0.73894 | H12: {='onepage_summary (6)'!H:H} -> #VALUE!
A13: 600 | B13: DF | C13: 10 | D13: 0.73567 | E13: 0.76163 | F13: 0.7361 | G13: 0.72961 | H13: {='onepage_summary (6)'!H:H} -> #VALUE!
... A65: 1000 | B65: VarCNN | C65: 10 | D65: 0.67586 | E65: 0.71701 | F65: 0.67622 | G65: 0.66297 | H65: {='onepage_summary (6)'!H:H} -> #VALUE!

Sheet Sheet1
A1: 5 | B1: PadL | C1: p_out - p_in | D1: DF Acc (CW_tamaraw) | E1: DF Precision (CW_Tamaraw) | F1: DF Recall (CW_Tamaraw) | G1: DF F1-score (CW_Tamaraw) | H1: Tik-Tok Acc (CW_tamaraw) | I1: Tik-Tok Precision (CW_Tamaraw) | J1: Tik-Tok Recall (CW_Tamaraw) | K1: Tik-Tok F1-score (CW_Tamaraw) | L1: Var-CNN Acc (CW_tamaraw) | M1: Var-CNN Precision (CW_Tamaraw) | N1: Var-CNN Recall (CW_Tamaraw) | O1: Var-CNN F1-score (CW_Tamaraw) | P1: RF Acc (CW_tamaraw) | Q1: RF Precision (CW_Tamaraw) | R1: RF Recall (CW_Tamaraw) | S1: RF F1-score (CW_Tamaraw) | T1: Overhead (if measured)
A3: Medium Tamaraw | B3: 25 | C3: 0.04 - 0.012 | D3: 0.0026 | E3: 0.0115 | F3: 0.0025 | G3: 0.001 | H3: 0.0107 | I3: 0.0004 | J3: 0.0106 | K3: 0.0007 | L3: 0.0105 | M3: 0.0001 | N3: 0.0105 | O3: 0.0002 | P3: 0.0107 | Q3: 0.0006 | R3: 0.0113 | S3: 0.0008 | T3: 1.1515
A5: Weak Tamaraw | B5: 25 | C5: 0.02 - 0.006 | D5: 0.1455 | E5: 0.1103 | F5: 0.1456 | G5: 0.1049 | H5: 0.0212 | I5: 0.0092 | J5: 0.0211 | K5: 0.0087 | L5: 0.0105 | M5: 0.0001 | N5: 0.0105 | O5: 0.0002 | P5: 0.0219 | Q5: 0.0169 | R5: 0.022 | S5: 0.0128 | T5: 3.3804
B6: 50 | C6: 0.02 - 0.006 | D6: 0.1941 | E6: 0.1221 | F6: 0.1941 | G6: 0.1332 | H6: 0.0164 | I6: 0.0092 | J6: 0.0163 | K6: 0.0096 | L6: 0.0105 | M6: 0.0001 | N6: 0.0105 | O6: 0.0002 | P6: 0.0184 | Q6: 0.0153 | R6: 0.0185 | S6: 0.0095 | T6: 3.4294
B7: 75 | C7: 0.02 - 0.006 | D7: 0.2021 | E7: 0.1272 | F7: 0.202 | G7: 0.1401 | H7: 0.0105 | I7: 0.0103 | J7: 0.0105 | K7: 0.0075 | L7: 0.0105 | M7: 0.0001 | N7: 0.0105 | O7: 0.0002 | P7: 0.0148 | Q7: 0.0122 | R7: 0.0149 | S7: 0.0059 | T7: 3.4789
B8: 100 | C8: 0.02 - 0.006 | D8: 0.2185 | E8: 0.1411 | F8: 0.2184 | G8: 0.1542 | H8: 0.0108 | I8: 0.0056 | J8: 0.0108 | K8: 0.0057 | L8: 0.0105 | M8: 0.0001 | N8: 0.0105 | O8: 0.0002 | P8: 0.0126 | Q8: 0.0076 | R8: 0.0127 | S8: 0.0035 | T8: 3.5273
B9: 125 | C9: 0.02 - 0.006 | D9: 0.2029 | E9: 0.1327 | F9: 0.2028 | G9: 0.1414 | H9: 0.0101 | I9: 0.0068 | J9: 0.0101 | K9: 0.007 | L9: 0.0105 | M9: 0.0001 | N9: 0.0105 | O9: 0.0002 | P9: 0.011 | Q9: 0.0076 | R9: 0.0111 | S9: 0.0023 | T9: 3.5764
B10: 150 | C10: 0.02 - 0.006 | D10: 0.2081 | E10: 0.1459 | F10: 0.2079 | G10: 0.1466 | H10: 0.0114 | I10: 0.0076 | J10: 0.0114 | K10: 0.0083 | L10: 0.0105 | M10: 0.0001 | N10: 0.0105 | O10: 0.0002 | P10: 0.0105 | Q10: 0.0021 | R10: 0.0106 | S10: 0.0015 | T10: 3.6255
B11: 175 | C11: 0.02 - 0.006 | D11: 0.2036 | E11: 0.1405 | F11: 0.2035 | G11: 0.1408 | H11: 0.0092 | I11: 0.007 | J11: 0.0091 | K11: 0.0073 | L11: 0.0105 | M11: 0.0001 | N11: 0.0105 | O11: 0.0002 | P11: 0.0107 | Q11: 0.0033 | R11: 0.0108 | S11: 0.0019 | T11: 3.6737
B12: 200 | C12: 0.02 - 0.006 | D12: 0.2108 | E12: 0.14 | F12: 0.2107 | G12: 0.1481 | H12: 0.0103 | I12: 0.0049 | J12: 0.0103 | K12: 0.0059 | L12: 0.0105 | M12: 0.0001 | N12: 0.0105 | O12: 0.0002 | P12: 0.0106 | Q12: 0.0055 | R12: 0.0107 | S12: 0.0018 | T12: 3.7246
A14: Medium Tamaraw | B14: 25 | C14: 0.04 - 0.012 | D14: 0.0026 | E14: 0.0115 | F14: 0.0025 | G14: 0.001 | H14: 0.0107 | I14: 0.0004 | J14: 0.0106 | K14: 0.0007 | L14: 0.0105 | M14: 0.0001 | N14: 0.0105 | O14: 0.0002 | P14: 0.0294 | Q14: 0.0145 | R14: 0.0294 | S14: 25 | T14: 1.1515 | U14: 115.15
B15: 50 | C15: 0.04 - 0.012 | D15: 0.0104 | E15: 0.0017 | F15: 0.0103 | G15: 0.0026 | S15: 50 | T15: 1.2003 | U15: 120.03
B16: 75 | C16: 0.04 - 0.012 | S16: 75 | T16: 1.2495 | U16: 124.95
B17: 100 | C17: 0.04 - 0.012 | D17: 0.0112 | E17: 0.0046 | F17: 0.0111 | G17: 0.0054 | S17: 100 | T17: 1.2985 | U17: 129.85
B18: 125 | C18: 0.04 - 0.012 | S18: 125 | T18: 1.3472 | U18: 134.72
B19: 150 | C19: 0.04 - 0.012 | S19: 150 | T19: 1.3967 | U19: 139.67
B20: 175 | C20: 0.04 - 0.012 | S20: 175 | T20: 1.4468 | U20: 144.68
B21: 200 | C21: 0.04 - 0.012 | S21: 200 | T21: 1.4944 | U21: 149.44
S22: 300 | T22: 1.6915 | U22: 169.15
A23: Strong Tamaraw | B23: 25 | C23: 0.08 - 0.024 | S23: 400 | T23: 1.8858 | U23: 188.58
B24: 50 | C24: 0.08 - 0.024 | S24: 500 | T24: 2.0837 | U24: 208.37
B25: 75 | C25: 0.08 - 0.024 | S25: 600 | T25: 2.2835 | U25: 228.35
B26: 100 | C26: 0.08 - 0.024 | S26: 700 | T26: 2.4755 | U26: 247.55
B27: 125 | C27: 0.08 - 0.024 | S27: 800 | T27: 2.6691 | U27: 266.91
B28: 150 | C28: 0.08 - 0.024 | S28: 900 | T28: 2.8717 | U28: 287.17
B29: 175 | C29: 0.08 - 0.024 | S29: 1000 | T29: 3.063 | U29: 306.3
B30: 200 | C30: 0.08 - 0.024 | D30: 0.0092 | E30: 0.0021 | F30: 0.0091 | G30: 0.0031 | S30: 1100 | T30: 3.2589 | U30: 325.89
S31: 1200 | T31: 3.4548 | U31: 345.48
S32: 1300 | T32: 3.65 | U32: 365
S33: 1400 | T33: 3.8526 | U33: 385.26
S34: 1500 | T34: 4.0419 | U34: 404.19
B64: 75 | C64: 0.04 | D64: 0.9893 | E64: 0.7171 | F64: 0.5176 | G64: 0.5304
D65: 0.9885 | E65: 0.4947 | F65: 0.4995 | G65: 0.4971
D66: 0.9886 | E66: 0.4947 | F66: 0.4996 | G66: 0.4971
D67: 0.9886 | E67: 0.4947 | F67: 0.4996 | G67: 0.4971
D68: 0.9889 | E68: 0.4948 | F68: 0.4996 | G68: 0.4972
D69: 0.9887 | E69: 0.4947 | F69: 0.4996 | G69: 0.4971
D70: 0.9884 | E70: 0.4947 | F70: 0.4995 | G70: 0.4971
D71: 0.9889 | E71: 0.5573 | F71: 0.5042 | G71: 0.5056
D72: 0.9883 | E72: 0.4947 | F72: 0.4994 | G72: 0.4971
...
